Workbook
Name COIN_CODE: [2]CODE!$C$2:$C$50
Name ISO_CODE: [3]CODE!$B$2:$B$239
Name ISO_N_CODE: [2]CODE!$B$2:$B$239
Name TARGET_T_CODE: [3]CODE!$F$2:$F$10
Name TEX_N_CODE: [2]CODE!$A$2:$A$239
Name 箱號: '[1]出倉入箱 '!#REF!

Sheet Silver bar list_
A2: Brink's ref. no. | B2: Pallet no. | C2: No. of bars | D2: Net weight (kg) | E2: Net weight (oz)
A3: AG43454 | B3: Pallet # 1 | C3: =COUNTIF($B$21:$B$190,B3) -> 34 | D3: =SUMIFS($D$21:$D$190,$B$21:$B$190,B3) -> 1005.1939 | E3: =D3*32.1507 -> 32317.688
A4: AG43454 | B4: Pallet # 2 | C4: =COUNTIF($B$21:$B$190,B4) -> 34 | D4: =SUMIFS($D$21:$D$190,$B$21:$B$190,B4) -> 1005.5214 | E4: =D4*32.1507 -> 32328.217
A5: AG43454 | B5: Pallet # 3 | C5: =COUNTIF($B$21:$B$190,B5) -> 34 | D5: =SUMIFS($D$21:$D$190,$B$21:$B$190,B5) -> 1005.2384 | E5: =D5*32.1507 -> 32319.118
A6: AG43454 | B6: Pallet # 4 | C6: =COUNTIF($B$21:$B$190,B6) -> 34 | D6: =SUMIFS($D$21:$D$190,$B$21:$B$190,B6) -> 1004.7048 | E6: =D6*32.1507 -> 32301.963
A10: AG43454 | B10: Pallet # 8 | C10: =COUNTIF($B$21:$B$190,B10) -> 34 | D10: =SUMIFS($D$21:$D$190,$B$21:$B$190,B10) -> 1004.4225 | E10: =D10*32.1507 -> 32292.886
A11: Total | B11: =COUNTA(B3:B10) -> 5 | C11: =SUM(C3:C10) -> 170 | D11: =SUM(D3:D10) -> 5025.081 | E11: =SUM(E3:E10) -> 161559.87
A14: Commodity: | B14: Silver bar
A15: Brand name: | B15: JTQX
A16: Pallet no.: | B16: 1-4,8
A17: Purity: | B17: 999.9
A20: Brand name | B20: Pallet no. | C20: Bar no. | D20: Net weight (kg) | E20: Net weight (oz)
A21: JTQX | B21: Pallet # 1 | C21: 022609127 | D21: 29.518 | E21: =D21*32.1507 -> 949.02436
A22: JTQX | B22: =B21 -> Pallet # 1 | C22: 022609128 | D22: 29.5676 | E22: =D22*32.1507 -> 950.61904
A23: JTQX | B23: =B22 -> Pallet # 1 | C23: 022609129 | D23: 29.5718 | E23: =D23*32.1507 -> 950.75407
A24: JTQX | B24: =B23 -> Pallet # 1 | C24: 022609141 | D24: 29.5816 | E24: =D24*32.1507 -> 951.06915
A25: JTQX | B25: =B24 -> Pallet # 1 | C25: 022609142 | D25: 29.5629 | E25: =D25*32.1507 -> 950.46793
A26: JTQX | B26: =B25 -> Pallet # 1 | C26: 022609143 | D26: 29.5632 | E26: =D26*32.1507 -> 950.47757
A27: JTQX | B27: =B26 -> Pallet # 1 | C27: 022609144 | D27: 29.5674 | E27: =D27*32.1507 -> 950.61261
A28: JTQX | B28: =B27 -> Pallet # 1 | C28: 022609145 | D28: 29.5245 | E28: =D28*32.1507 -> 949.23334
A29: JTQX | B29: =B28 -> Pallet # 1 | C29: 022609146 | D29: 29.5864 | E29: =D29*32.1507 -> 951.22347
A30: JTQX | B30: =B29 -> Pallet # 1 | C30: 022609147 | D30: 29.5654 | E30: =D30*32.1507 -> 950.54831
A31: JTQX | B31: =B30 -> Pallet # 1 | C31: 022609148 | D31: 29.6253 | E31: =D31*32.1507 -> 952.47413
A32: JTQX | B32: =B31 -> Pallet # 1 | C32: 022609149 | D32: 29.5631 | E32: =D32*32.1507 -> 950.47436
A33: JTQX | B33: =B32 -> Pallet # 1 | C33: 022609150 | D33: 29.544 | E33: =D33*32.1507 -> 949.86028
... A54: JTQX | B54: =B53 -> Pallet # 1 | C54: 022609174 | D54: 29.5646 | E54: =D54*32.1507 -> 950.52259
A55: JTQX | B55: Pallet # 2 | C55: 022609175 | D55: 29.6812 | E55: =D55*32.1507 -> 954.27136
A56: JTQX | B56: =B55 -> Pallet # 2 | C56: 022609176 | D56: 29.5559 | E56: =D56*32.1507 -> 950.24287
A57: JTQX | B57: =B56 -> Pallet # 2 | C57: 022609177 | D57: 29.4951 | E57: =D57*32.1507 -> 948.28811
A58: JTQX | B58: =B57 -> Pallet # 2 | C58: 022609178 | D58: 29.5424 | E58: =D58*32.1507 -> 949.80884
A59: JTQX | B59: =B58 -> Pallet # 2 | C59: 022609179 | D59: 29.5145 | E59: =D59*32.1507 -> 948.91184
A60: JTQX | B60: =B59 -> Pallet # 2 | C60: 022609180 | D60: 29.5387 | E60: =D60*32.1507 -> 949.68988
A61: JTQX | B61: =B60 -> Pallet # 2 | C61: 022609181 | D61: 29.5525 | E61: =D61*32.1507 -> 950.13356
A62: JTQX | B62: =B61 -> Pallet # 2 | C62: 022609182 | D62: 29.546 | E62: =D62*32.1507 -> 949.92458
A63: JTQX | B63: =B62 -> Pallet # 2 | C63: 022609183 | D63: 29.5163 | E63: =D63*32.1507 -> 948.96971
A64: JTQX | B64: =B63 -> Pallet # 2 | C64: 022609184 | D64: 29.5411 | E64: =D64*32.1507 -> 949.76704
A65: JTQX | B65: =B64 -> Pallet # 2 | C65: 022609185 | D65: 29.6805 | E65: =D65*32.1507 -> 954.24885
A66: JTQX | B66: =B65 -> Pallet # 2 | C66: 022609186 | D66: 29.5632 | E66: =D66*32.1507 -> 950.47757
A67: JTQX | B67: =B66 -> Pallet # 2 | C67: 022609187 | D67: 29.6116 | E67: =D67*32.1507 -> 952.03367
... A88: JTQX | B88: =B87 -> Pallet # 2 | C88: 022610112 | D88: 29.5522 | E88: =D88*32.1507 -> 950.12392
...

Sheet Silver bar list
A2: ='Silver bar list_'!A2 -> Brink's ref. no. | B2: ='Silver bar list_'!B2 -> Pallet no. | C2: ='Silver bar list_'!C2 -> No. of bars | D2: ='Silver bar list_'!D2 -> Net weight (kg)
A3: ='Silver bar list_'!A4 -> AG43454 | B3: Pallet # 2 | C3: =D9 -> 34 | D3: =C28 -> 1005.5214
A4: ='Silver bar list_'!A10 -> AG43454 | B4: Pallet # 8 | C4: =D32 -> 34 | D4: =C51 -> 1004.4225
A5: Total | B5: =COUNTA(B3:B4) -> 2 | C5: =SUM(C3:C4) -> 68 | D5: =SUM(D3:D4) -> 2009.9439
A9: =A3 -> AG43454 | B9: =B3 -> Pallet # 2 | C9: No. of bars: | D9: =COUNT(B11:B27,D11:D27) -> 34
A10: Bar no. | B10: Net weight (kg) | C10: Bar no. | D10: Net weight (kg)
A11: ='Silver bar list_'!C55 -> 022609175 | B11: ='Silver bar list_'!D55 -> 29.6812 | C11: ='Silver bar list_'!C72 -> 022609192 | D11: ='Silver bar list_'!D72 -> 29.5474
A12: ='Silver bar list_'!C56 -> 022609176 | B12: ='Silver bar list_'!D56 -> 29.5559 | C12: ='Silver bar list_'!C73 -> 022609193 | D12: ='Silver bar list_'!D73 -> 29.5313
A13: ='Silver bar list_'!C57 -> 022609177 | B13: ='Silver bar list_'!D57 -> 29.4951 | C13: ='Silver bar list_'!C74 -> 022609194 | D13: ='Silver bar list_'!D74 -> 29.5367
A14: ='Silver bar list_'!C58 -> 022609178 | B14: ='Silver bar list_'!D58 -> 29.5424 | C14: ='Silver bar list_'!C75 -> 022609195 | D14: ='Silver bar list_'!D75 -> 29.5621
A15: ='Silver bar list_'!C59 -> 022609179 | B15: ='Silver bar list_'!D59 -> 29.5145 | C15: ='Silver bar list_'!C76 -> 022609196 | D15: ='Silver bar list_'!D76 -> 29.608
A16: ='Silver bar list_'!C60 -> 022609180 | B16: ='Silver bar list_'!D60 -> 29.5387 | C16: ='Silver bar list_'!C77 -> 022610101 | D16: ='Silver bar list_'!D77 -> 29.7076
A17: ='Silver bar list_'!C61 -> 022609181 | B17: ='Silver bar list_'!D61 -> 29.5525 | C17: ='Silver bar list_'!C78 -> 022610102 | D17: ='Silver bar list_'!D78 -> 29.5577
A18: ='Silver bar list_'!C62 -> 022609182 | B18: ='Silver bar list_'!D62 -> 29.546 | C18: ='Silver bar list_'!C79 -> 022610103 | D18: ='Silver bar list_'!D79 -> 29.5697
A19: ='Silver bar list_'!C63 -> 022609183 | B19: ='Silver bar list_'!D63 -> 29.5163 | C19: ='Silver bar list_'!C80 -> 022610104 | D19: ='Silver bar list_'!D80 -> 29.5716
A20: ='Silver bar list_'!C64 -> 022609184 | B20: ='Silver bar list_'!D64 -> 29.5411 | C20: ='Silver bar list_'!C81 -> 022610105 | D20: ='Silver bar list_'!D81 -> 29.5984
A21: ='Silver bar list_'!C65 -> 022609185 | B21: ='Silver bar list_'!D65 -> 29.6805 | C21: ='Silver bar list_'!C82 -> 022610106 | D21: ='Silver bar list_'!D82 -> 29.5623
A22: ='Silver bar list_'!C66 -> 022609186 | B22: ='Silver bar list_'!D66 -> 29.5632 | C22: ='Silver bar list_'!C83 -> 022610107 | D22: ='Silver bar list_'!D83 -> 29.5437
... A27: ='Silver bar list_'!C71 -> 022609191 | B27: ='Silver bar list_'!D71 -> 29.5466 | C27: ='Silver bar list_'!C88 -> 022610112 | D27: ='Silver bar list_'!D88 -> 29.5522
A28: Total (kg) | C28: =SUM(B11:B27,D11:D27) -> 1005.5214
A32: =A4 -> AG43454 | B32: =B4 -> Pallet # 8 | C32: No. of bars: | D32: =COUNT(B34:B50,D34:D50) -> 34
A33: Bar no. | B33: Net weight (kg) | C33: Bar no. | D33: Net weight (kg)
A34: ='Silver bar list_'!C157 -> 022613106 | B34: ='Silver bar list_'!D157 -> 29.5301 | C34: ='Silver bar list_'!C174 -> 022613124 | D34: ='Silver bar list_'!D174 -> 29.5344
A35: ='Silver bar list_'!C158 -> 022613107 | B35: ='Silver bar list_'!D158 -> 29.5108 | C35: ='Silver bar list_'!C175 -> 022613125 | D35: ='Silver bar list_'!D175 -> 29.5098
A36: ='Silver bar list_'!C159 -> 022613108 | B36: ='Silver bar list_'!D159 -> 29.5358 | C36: ='Silver bar list_'!C176 -> 022613126 | D36: ='Silver bar list_'!D176 -> 29.5414
A37: ='Silver bar list_'!C160 -> 022613109 | B37: ='Silver bar list_'!D160 -> 29.5296 | C37: ='Silver bar list_'!C177 -> 022613151 | D37: ='Silver bar list_'!D177 -> 29.532
A38: ='Silver bar list_'!C161 -> 022613110 | B38: ='Silver bar list_'!D161 -> 29.5608 | C38: ='Silver bar list_'!C178 -> 022613155 | D38: ='Silver bar list_'!D178 -> 29.5124
A39: ='Silver bar list_'!C162 -> 022613111 | B39: ='Silver bar list_'!D162 -> 29.5323 | C39: ='Silver bar list_'!C179 -> 022613157 | D39: ='Silver bar list_'!D179 -> 29.5099
A40: ='Silver bar list_'!C163 -> 022613112 | B40: ='Silver bar list_'!D163 -> 29.647 | C40: ='Silver bar list_'!C180 -> 022613159 | D40: ='Silver bar list_'!D180 -> 29.516
A41: ='Silver bar list_'!C164 -> 022613113 | B41: ='Silver bar list_'!D164 -> 29.6552 | C41: ='Silver bar list_'!C181 -> 022613127 | D41: ='Silver bar list_'!D181 -> 29.5283
A42: ='Silver bar list_'!C165 -> 022613114 | B42: ='Silver bar list_'!D165 -> 29.556 | C42: ='Silver bar list_'!C182 -> 022613128 | D42: ='Silver bar list_'!D182 -> 29.5328
A43: ='Silver bar list_'!C166 -> 022613115 | B43: ='Silver bar list_'!D166 -> 29.5452 | C43: ='Silver bar list_'!C183 -> 022613129 | D43: ='Silver bar list_'!D183 -> 29.5469
A44: ='Silver bar list_'!C167 -> 022613117 | B44: ='Silver bar list_'!D167 -> 29.549 | C44: ='Silver bar list_'!C184 -> 022613130 | D44: ='Silver bar list_'!D184 -> 29.5425
A45: ='Silver bar list_'!C168 -> 022613118 | B45: ='Silver bar list_'!D168 -> 29.5502 | C45: ='Silver bar list_'!C185 -> 022613131 | D45: ='Silver bar list_'!D185 -> 29.5304
... A50: ='Silver bar list_'!C173 -> 022613123 | B50: ='Silver bar list_'!D173 -> 29.4995 | C50: ='Silver bar list_'!C190 -> 022613136 | D50: ='Silver bar list_'!D190 -> 29.5556
A51: Total (kg) | C51: =SUM(B34:B50,D34:D50) -> 1004.4225
